<?xml version="1.0"?>
<robot name="single_joint_actuator">
    <material name="gray">
	    <color rgba="0.5 0.5 0.5 1"/>
    </material>

    <material name="white">
	    <color rgba="1.0 1.0 1.0 1"/>
    </material>

    <material name="blue">
	    <color rgba="0.0 0.0 1.0 1"/>
    </material>


    <link name="wolrd"/>

    <joint name="wolrd_motor" type="fixed">
        <parent link="wolrd"/>
        <child link="motor"/>
    </joint>

    <link name="motor">
        <visual>
            <geometry>
                <cylinder radius="0.025" length="0.07"/>
            </geometry>
            <origin xyz="0.0 0.0 0.0" rpy="0.0 1.5708 0.0"/>
            <material name="gray"/>
        </visual>
    </link>

    <joint name="joint1" type="continuous">
        <parent link="motor"/>
        <child link="eje"/>
        <axis xyz="1 0 0"/>
        <origin xyz="0.045 0 0" rpy="0 0 0"/>
    </joint>

    <link name="eje">
        <visual>
            <origin xyz="0.0 0.0 0.0" rpy="0.0 1.5708 0.0"/>
            <geometry>
                <cylinder radius="0.004" length="0.02"/>                
            </geometry>
            <material name="white"/>
        </visual>
    </link>

    <joint name="eje_arm" type="fixed">
        <parent link="eje"/>
        <child link="arm"/>
        <origin xyz="0.01 0.0 0.0" rpy="0.0 0.0 0.0"/>
    </joint>

    <link name="arm">
        <visual>
            <origin xyz="0.0 0.0 0.025" rpy="0.0 0.0 0.0"/>
            <geometry>
                <box size="0.001 0.02 0.05"/>
            </geometry>
            <material name="blue"/>
        </visual>
    </link>
</robot>